Workbook

Sheet Event Calendar
A1: Event | B1: Start | C1: End | D1: Venue | E1: Area | F1: Sector | G1: Total Attendance | H1: Exhibitors | I1: Primary Source Markets (Top Countries) | J1: Data Status | K1: Out-of-town % Low | L1: Out-of-town % High | M1: Avg Stay Low (nts) | N1: Avg Stay High (nts) | O1: Persons/Room | P1: Market Room Nights Low | Q1: Market Room Nights High | R1: Lakeview Capture Low | S1: Lakeview Capture High | T1: Lakeview Room Nights Low | U1: Lakeview Room Nights High | V1: Hotel Impact | W1: DIP Area ADR Low (AED) | X1: DIP Area ADR High (AED) | Y1: Planning Status | Z1: Source / Verification Note | AA1: Month Key
A2: Middle East Energy | B2: 46266 | C2: 46268 | D2: Dubai World Trade Centre | E2: DWTC | F2: Energy | G2: 45000 | H2: 1900 | I2: 131+ countries confirmed (2026); top international markets Nigeria, Egypt, Saudi Arabia | J2: Planning estimate (2026 organizer projection) | K2: 0.3 | L2: 0.45 | M2: 2 | N2: 3 | O2: 1.4 | P2: =IFERROR(ROUND(G2*K2*M2/O2,0),"") -> 19286 | Q2: =IFERROR(ROUND(G2*L2*N2/O2,0),"") -> 43393 | R2: 0.002 | S2: 0.007 | T2: =IFERROR(ROUND(P2*R2,0),"") -> 39 | U2: =IFERROR(ROUND(Q2*S2,0),"") -> 304 | V2: HIGH | W2: =ROUND(Methodology!$B$11*IF(V2="VERY HIGH",1.3,IF(V2="HIGH",1.18,1.08)),0) -> 448 | X2: =ROUND(Methodology!$B$11*IF(V2="VERY HIGH",1.45,IF(V2="HIGH",1.3,1.15)),0) -> 494 | Y2: Confirmed | Z2: NEW — added to calendar; date moved from 7–9 Apr to 1–3 Sep 2026 (organizer notice). | AA2: =TEXT(B2,"yyyy-mm") -> 2026-09
A3: Dubai Derma | B3: 46273 | C3: 46275 | D3: Dubai World Trade Centre | E3: DWTC | F3: Healthcare | G3: 25000 | H3: 1875 | I3: 114 countries; strong MENA / Asia / Europe medical-professional draw | J3: Planning estimate | K3: 0.3 | L3: 0.45 | M3: 2 | N3: 3 | O3: 1.4 | P3: =IFERROR(ROUND(G3*K3*M3/O3,0),"") -> 10714 | Q3: =IFERROR(ROUND(G3*L3*N3/O3,0),"") -> 24107 | R3: 0.001 | S3: 0.004 | T3: =IFERROR(ROUND(P3*R3,0),"") -> 11 | U3: =IFERROR(ROUND(Q3*S3,0),"") -> 96 | V3: HIGH | W3: =ROUND(Methodology!$B$11*IF(V3="VERY HIGH",1.3,IF(V3="HIGH",1.18,1.08)),0) -> 448 | X3: =ROUND(Methodology!$B$11*IF(V3="VERY HIGH",1.45,IF(V3="HIGH",1.3,1.15)),0) -> 494 | Y3: Confirmed | Z3: NEW — added to calendar; confirmed 8–10 Sep 2026. | AA3: =TEXT(B3,"yyyy-mm") -> 2026-09
A4: Arabian Travel Market | B4: 46279 | C4: 46282 | D4: Dubai World Trade Centre | E4: DWTC | F4: Travel & Tourism | G4: 50000 | H4: 2600 | I4: 166 countries (2025 actual); top international markets India, Egypt, UK, Türkiye, USA | J4: Planning estimate; 2025 actual 55,000 visitors/166 countries; 2026 organizer projection 47,000+/160+ countries | K4: 0.45 | L4: 0.6 | M4: 2.5 | N4: 3.5 | O4: 1.4 | P4: =IFERROR(ROUND(G4*K4*M4/O4,0),"") -> 40179 | Q4: =IFERROR(ROUND(G4*L4*N4/O4,0),"") -> 75000 | R4: 0.002 | S4: 0.007 | T4: =IFERROR(ROUND(P4*R4,0),"") -> 80 | U4: =IFERROR(ROUND(Q4*S4,0),"") -> 525 | V4: HIGH | W4: =ROUND(Methodology!$B$11*IF(V4="VERY HIGH",1.3,IF(V4="HIGH",1.18,1.08)),0) -> 448 | X4: =ROUND(Methodology!$B$11*IF(V4="VERY HIGH",1.45,IF(V4="HIGH",1.3,1.15)),0) -> 494 | Y4: Confirmed | Z4: NEW — previously missing from model despite being a top citywide driver; date finalised 14–17 Sep 2026 after two reschedules (orig. May, then Aug). | AA4: =TEXT(B4,"yyyy-mm") -> 2026-09
A5: GISEC Global | B5: 46281 | C5: 46283 | D5: Dubai Exhibition Centre | E5: Expo City / DEC | F5: Cybersecurity | G5: 15000 | H5: 700 | I5: 182+ countries (2026 projection) | J5: Planning estimate | K5: 0.2 | L5: 0.35 | M5: 1.8 | N5: 2.5 | O5: 1.4 | P5: =IFERROR(ROUND(G5*K5*M5/O5,0),"") -> 3857 | Q5: =IFERROR(ROUND(G5*L5*N5/O5,0),"") -> 9375 | R5: 0.002 | S5: 0.008 | T5: =IFERROR(ROUND(P5*R5,0),"") -> 8 | U5: =IFERROR(ROUND(Q5*S5,0),"") -> 75 | V5: MEDIUM | W5: =ROUND(Methodology!$B$11*IF(V5="VERY HIGH",1.3,IF(V5="HIGH",1.18,1.08)),0) -> 410 | X5: =ROUND(Methodology!$B$11*IF(V5="VERY HIGH",1.45,IF(V5="HIGH",1.3,1.15)),0) -> 437 | Y5: Confirmed | AA5: =TEXT(B5,"yyyy-mm") -> 2026-09
A6: Seamless Middle East (2026) | B6: 46287 | C6: 46289 | D6: Dubai World Trade Centre | E6: DWTC | F6: Fintech / Payments | G6: 20000 | H6: 750 | I6: Not published for this edition | J6: ⚠ Dates unconfirmed — sources conflict (12–14 May vs 22–24 Sep 2026, rebrand 'Seamless Digital Commerce ME'); verify with organiser (Terrapinn) before blocking rooms. | K6: 0.25 | L6: 0.4 | M6: 1.8 | N6: 2.5 | O6: 1.4 | P6: =IFERROR(ROUND(G6*K6*M6/O6,0),"") -> 6429 | Q6: =IFERROR(ROUND(G6*L6*N6/O6,0),"") -> 14286 | R6: 0.001 | S6: 0.004 | T6: =IFERROR(ROUND(P6*R6,0),"") -> 6 | U6: =IFERROR(ROUND(Q6*S6,0),"") -> 57 | V6: MEDIUM | W6: =ROUND(Methodology!$B$11*IF(V6="VERY HIGH",1.3,IF(V6="HIGH",1.18,1.08)),0) -> 410 | X6: =ROUND(Methodology!$B$11*IF(V6="VERY HIGH",1.45,IF(V6="HIGH",1.3,1.15)),0) -> 437 | Y6: TBC / Benchmark | Z6: NEW — added to calendar; confirm final date before committing inventory. | AA6: =TEXT(B6,"yyyy-mm") -> 2026-09
A7: Middle East Coatings Show | B7: 46293 | C7: 46295 | D7: Dubai Exhibition Centre | E7: Expo City / DEC | F7: Industrial | G7: 10000 | H7: 500 | I7: 24+ countries | J7: Planning estimate | K7: 0.2 | L7: 0.35 | M7: 1.8 | N7: 2.5 | O7: 1.4 | P7: =IFERROR(ROUND(G7*K7*M7/O7,0),"") -> 2571 | Q7: =IFERROR(ROUND(G7*L7*N7/O7,0),"") -> 6250 | R7: 0.002 | S7: 0.008 | T7: =IFERROR(ROUND(P7*R7,0),"") -> 5 | U7: =IFERROR(ROUND(Q7*S7,0),"") -> 50 | V7: MEDIUM | W7: =ROUND(Methodology!$B$11*IF(V7="VERY HIGH",1.3,IF(V7="HIGH",1.18,1.08)),0) -> 410 | X7: =ROUND(Methodology!$B$11*IF(V7="VERY HIGH",1.45,IF(V7="HIGH",1.3,1.15)),0) -> 437 | Y7: Confirmed | AA7: =TEXT(B7,"yyyy-mm") -> 2026-09
A8: CABSAT + SAT Expo | B8: 46300 | C8: 46302 | D8: Dubai Exhibition Centre | E8: Expo City / DEC | F8: Broadcasting / Tech | G8: 15000 | H8: 500 | I8: Not published | J8: Planning estimate | K8: 0.2 | L8: 0.35 | M8: 1.8 | N8: 2.5 | O8: 1.4 | P8: =IFERROR(ROUND(G8*K8*M8/O8,0),"") -> 3857 | Q8: =IFERROR(ROUND(G8*L8*N8/O8,0),"") -> 9375 | R8: 0.002 | S8: 0.008 | T8: =IFERROR(ROUND(P8*R8,0),"") -> 8 | U8: =IFERROR(ROUND(Q8*S8,0),"") -> 75 | V8: MEDIUM | W8: =ROUND(Methodology!$B$11*IF(V8="VERY HIGH",1.3,IF(V8="HIGH",1.18,1.08)),0) -> 410 | X8: =ROUND(Methodology!$B$11*IF(V8="VERY HIGH",1.45,IF(V8="HIGH",1.3,1.15)),0) -> 437 | Y8: Confirmed | AA8: =TEXT(B8,"yyyy-mm") -> 2026-10
A9: Beautyworld Dubai | B9: 46301 | C9: 46303 | D9: DWTC | E9: DWTC | F9: Beauty | G9: 85291 | H9: 1966 | I9: 178 countries (2025 actual); top international markets UK, USA, France, India, Italy, Spain | J9: 2025 actual benchmark (85,291 visitors / 178 countries) | K9: 0.25 | L9: 0.4 | M9: 2 | N9: 3 | O9: 1.4 | P9: =IFERROR(ROUND(G9*K9*M9/O9,0),"") -> 30461 | Q9: =IFERROR(ROUND(G9*L9*N9/O9,0),"") -> 73107 | R9: 0.002 | S9: 0.007 | T9: =IFERROR(ROUND(P9*R9,0),"") -> 61 | U9: =IFERROR(ROUND(Q9*S9,0),"") -> 512 | V9: HIGH | W9: =ROUND(Methodology!$B$11*IF(V9="VERY HIGH",1.3,IF(V9="HIGH",1.18,1.08)),0) -> 448 | X9: =ROUND(Methodology!$B$11*IF(V9="VERY HIGH",1.45,IF(V9="HIGH",1.3,1.15)),0) -> 494 | Y9: Confirmed | Z9: CORRECTED — attendance updated from 71,439 (2024 benchmark) to 85,291 (2025 actual). | AA9: =TEXT(B9,"yyyy-mm") -> 2026-10
A10: Airport Show + Global Airport Leaders Forum | B10: 46307 | C10: 46309 | D10: DWTC | E10: DWTC | F10: Aviation | G10: 20000 | H10: 300 | I10: Not published | J10: Planning estimate | K10: 0.2 | L10: 0.35 | M10: 1.8 | N10: 2.5 | O10: 1.4 | P10: =IFERROR(ROUND(G10*K10*M10/O10,0),"") -> 5143 | Q10: =IFERROR(ROUND(G10*L10*N10/O10,0),"") -> 12500 | R10: 0.001 | S10: 0.004 | T10: =IFERROR(ROUND(P10*R10,0),"") -> 5 | U10: =IFERROR(ROUND(Q10*S10,0),"") -> 50 | V10: MEDIUM | W10: =ROUND(Methodology!$B$11*IF(V10="VERY HIGH",1.3,IF(V10="HIGH",1.18,1.08)),0) -> 410 | X10: =ROUND(Methodology!$B$11*IF(V10="VERY HIGH",1.45,IF(V10="HIGH",1.3,1.15)),0) -> 437 | Y10: Confirmed | AA10: =TEXT(B10,"yyyy-mm") -> 2026-10
A11: WETEX | B11: 46315 | C11: 46317 | D11: DWTC | E11: DWTC | F11: Energy / Sustainability | G11: 50000 | H11: 3100 | I11: 65 countries; 18 country pavilions; DEWA-led international energy/utility delegations | J11: 2025 actual benchmark (50,000+ visitors / 65 countries) | K11: 0.2 | L11: 0.35 | M11: 1.8 | N11: 2.5 | O11: 1.4 | P11: =IFERROR(ROUND(G11*K11*M11/O11,0),"") -> 12857 | Q11: =IFERROR(ROUND(G11*L11*N11/O11,0),"") -> 31250 | R11: 0.001 | S11: 0.004 | T11: =IFERROR(ROUND(P11*R11,0),"") -> 13 | U11: =IFERROR(ROUND(Q11*S11,0),"") -> 125 | V11: MEDIUM | W11: =ROUND(Methodology!$B$11*IF(V11="VERY HIGH",1.3,IF(V11="HIGH",1.18,1.08)),0) -> 410 | X11: =ROUND(Methodology!$B$11*IF(V11="VERY HIGH",1.45,IF(V11="HIGH",1.3,1.15)),0) -> 437 | Y11: Confirmed | Z11: CORRECTED — attendance updated from 35,000 to 50,000 (2025 actual). | AA11: =TEXT(B11,"yyyy-mm") -> 2026-10
A12: Baby & Kids Expo | B12: 46317 | C12: 46319 | D12: Dubai Exhibition Centre | E12: Expo City / DEC | F12: Consumer | G12: 12000 | H12: 250 | I12: Predominantly GCC / regional consumer visitors | J12: Planning estimate | K12: 0.2 | L12: 0.35 | M12: 1.8 | N12: 2.5 | O12: 1.4 | P12: =IFERROR(ROUND(G12*K12*M12/O12,0),"") -> 3086 | Q12: =IFERROR(ROUND(G12*L12*N12/O12,0),"") -> 7500 | R12: 0.002 | S12: 0.008 | T12: =IFERROR(ROUND(P12*R12,0),"") -> 6 | U12: =IFERROR(ROUND(Q12*S12,0),"") -> 60 | V12: MEDIUM | W12: =ROUND(Methodology!$B$11*IF(V12="VERY HIGH",1.3,IF(V12="HIGH",1.18,1.08)),0) -> 410 | X12: =ROUND(Methodology!$B$11*IF(V12="VERY HIGH",1.45,IF(V12="HIGH",1.3,1.15)),0) -> 437 | Y12: Confirmed | AA12: =TEXT(B12,"yyyy-mm") -> 2026-10
A13: Jewellery, Gem & Technology in Dubai | B13: 46322 | C13: 46324 | D13: Dubai Exhibition Centre | E13: Expo City / DEC | F13: Jewellery | G13: 10000 | H13: 400 | I13: Not published | J13: Planning estimate | K13: 0.2 | L13: 0.35 | M13: 1.8 | N13: 2.5 | O13: 1.4 | P13: =IFERROR(ROUND(G13*K13*M13/O13,0),"") -> 2571 | Q13: =IFERROR(ROUND(G13*L13*N13/O13,0),"") -> 6250 | R13: 0.002 | S13: 0.008 | T13: =IFERROR(ROUND(P13*R13,0),"") -> 5 | U13: =IFERROR(ROUND(Q13*S13,0),"") -> 50 | V13: MEDIUM | W13: =ROUND(Methodology!$B$11*IF(V13="VERY HIGH",1.3,IF(V13="HIGH",1.18,1.08)),0) -> 410 | X13: =ROUND(Methodology!$B$11*IF(V13="VERY HIGH",1.45,IF(V13="HIGH",1.3,1.15)),0) -> 437 | Y13: Confirmed | AA13: =TEXT(B13,"yyyy-mm") -> 2026-10
A14: Dubai Muscle Show / Active Show | B14: 46325 | C14: 46327 | D14: Dubai Exhibition Centre | E14: Expo City / DEC | F14: Fitness | G14: 45000 | H14: 450 | I14: Predominantly GCC / regional fitness community; growing international athlete draw | J14: Published | K14: 0.2 | L14: 0.35 | M14: 1.8 | N14: 2.5 | O14: 1.4 | P14: =IFERROR(ROUND(G14*K14*M14/O14,0),"") -> 11571 | Q14: =IFERROR(ROUND(G14*L14*N14/O14,0),"") -> 28125 | R14: 0.002 | S14: 0.008 | T14: =IFERROR(ROUND(P14*R14,0),"") -> 23 | U14: =IFERROR(ROUND(Q14*S14,0),"") -> 225 | V14: HIGH | W14: =ROUND(Methodology!$B$11*IF(V14="VERY HIGH",1.3,IF(V14="HIGH",1.18,1.08)),0) -> 448 | X14: =ROUND(Methodology!$B$11*IF(V14="VERY HIGH",1.45,IF(V14="HIGH",1.3,1.15)),0) -> 494 | Y14: Confirmed | AA14: =TEXT(B14,"yyyy-mm") -> 2026-10
A15: Gulfood Manufacturing | B15: 46329 | C15: 46331 | D15: DWTC | E15: DWTC | F15: F&B Manufacturing | G15: 61907 | H15: 2500 | I15: Global F&B processing / manufacturing buyers — GCC, Africa, South Asia, Europe (detailed breakdown not published) | J15: Published benchmark | K15: 0.35 | L15: 0.5 | M15: 2.5 | N15: 3.5 | O15: 1.4 | P15: =IFERROR(ROUND(G15*K15*M15/O15,0),"") -> 38692 | Q15: =IFERROR(ROUND(G15*L15*N15/O15,0),"") -> 77384 | R15: 0.003 | S15: 0.008 | T15: =IFERROR(ROUND(P15*R15,0),"") -> 116 | U15: =IFERROR(ROUND(Q15*S15,0),"") -> 619 | V15: HIGH | W15: =ROUND(Methodology!$B$11*IF(V15="VERY HIGH",1.3,IF(V15="HIGH",1.18,1.08)),0) -> 448 | X15: =ROUND(Methodology!$B$11*IF(V15="VERY HIGH",1.45,IF(V15="HIGH",1.3,1.15)),0) -> 494 | Y15: Confirmed | AA15: =TEXT(B15,"yyyy-mm") -> 2026-11
A16: Automechanika Dubai | B16: 46336 | C16: 46338 | D16: Dubai Exhibition Centre | E16: Expo City / DEC | F16: Automotive | G16: 50408 | H16: 2273 | I16: 162 countries (2025 actual); top markets Saudi Arabia, Iran, India, China, Iraq | J16: 2025 actual benchmark | K16: 0.25 | L16: 0.4 | M16: 2 | N16: 3 | O16: 1.4 | P16: =IFERROR(ROUND(G16*K16*M16/O16,0),"") -> 18003 | Q16: =IFERROR(ROUND(G16*L16*N16/O16,0),"") -> 43207 | R16: 0.002 | S16: 0.007 | T16: =IFERROR(ROUND(P16*R16,0),"") -> 36 | U16: =IFERROR(ROUND(Q16*S16,0),"") -> 302 | V16: HIGH | W16: =ROUND(Methodology!$B$11*IF(V16="VERY HIGH",1.3,IF(V16="HIGH",1.18,1.08)),0) -> 448 | X16: =ROUND(Methodology!$B$11*IF(V16="VERY HIGH",1.45,IF(V16="HIGH",1.3,1.15)),0) -> 494 | Y16: Confirmed | Z16: Refined to 50,408 (2025 actual, was 50,308 planning estimate). | AA16: =TEXT(B16,"yyyy-mm") -> 2026-11
A17: Big 5 Global | B17: 46349 | C17: 46352 | D17: DWTC | E17: DWTC | F17: Construction | G17: 85000 | H17: 2500 | I17: 150+ countries (2024 actual); top markets UAE, Saudi Arabia, Turkey, Italy, China, India, Germany, USA | J17: 2024 actual benchmark (85,000 visitors / 150+ countries) | K17: 0.25 | L17: 0.4 | M17: 2 | N17: 3 | O17: 1.4 | P17: =IFERROR(ROUND(G17*K17*M17/O17,0),"") -> 30357 | Q17: =IFERROR(ROUND(G17*L17*N17/O17,0),"") -> 72857 | R17: 0.002 | S17: 0.007 | T17: =IFERROR(ROUND(P17*R17,0),"") -> 61 | U17: =IFERROR(ROUND(Q17*S17,0),"") -> 510 | V17: HIGH | W17: =ROUND(Methodology!$B$11*IF(V17="VERY HIGH",1.3,IF(V17="HIGH",1.18,1.08)),0) -> 448 | X17: =ROUND(Methodology!$B$11*IF(V17="VERY HIGH",1.45,IF(V17="HIGH",1.3,1.15)),0) -> 494 | Y17: Confirmed | Z17: CORRECTED — attendance updated from 65,000 to 85,000 (2024 actual). | AA17: =TEXT(B17,"yyyy-mm") -> 2026-11
A18: GITEX Global | B18: 46363 | C18: 46367 | D18: Dubai Exhibition Centre | E18: Expo City / DEC | F18: Technology | G18: 200000 | H18: 6800 | I18: 180+ countries (2025); major delegations incl. India, Pakistan, Saudi Arabia, Egypt, UK, USA, China; 2025 Country Partner: Brazil | J18: 2025 actual benchmark (200,000+ visitors) | K18: 0.25 | L18: 0.4 | M18: 2 | N18: 3 | O18: 1.4 | P18: =IFERROR(ROUND(G18*K18*M18/O18,0),"") -> 71429 | Q18: =IFERROR(ROUND(G18*L18*N18/O18,0),"") -> 171429 | R18: 0.002 | S18: 0.006 | T18: =IFERROR(ROUND(P18*R18,0),"") -> 143 | U18: =IFERROR(ROUND(Q18*S18,0),"") -> 1029 | V18: VERY HIGH | W18: =ROUND(Methodology!$B$11*IF(V18="VERY HIGH",1.3,IF(V18="HIGH",1.18,1.08)),0) -> 494 | X18: =ROUND(Methodology!$B$11*IF(V18="VERY HIGH",1.45,IF(V18="HIGH",1.3,1.15)),0) -> 551 | Y18: Confirmed | Z18: CORRECTED — attendance updated from 100,000 (planning estimate) to 200,000 (2024/2025 actual); major upward revision. | AA18: =TEXT(B18,"yyyy-mm") -> 2026-12
A19: Intersec Global | B19: 46399 | C19: 46401 | D19: DWTC | E19: DWTC | F19: Security | G19: 44764 | H19: 1180 | I19: 151 countries (2026 actual); 60% domestic / 40% international; key markets USA, China, India, South Korea, France, Germany, Italy, Türkiye, UK | J19: 2026 actual benchmark | K19: 0.2 | L19: 0.35 | M19: 1.8 | N19: 2.5 | O19: 1.4 | P19: =IFERROR(ROUND(G19*K19*M19/O19,0),"") -> 11511 | Q19: =IFERROR(ROUND(G19*L19*N19/O19,0),"") -> 27978 | R19: 0.001 | S19: 0.004 | T19: =IFERROR(ROUND(P19*R19,0),"") -> 12 | U19: =IFERROR(ROUND(Q19*S19,0),"") -> 112 | V19: MEDIUM | W19: =ROUND(Methodology!$B$11*IF(V19="VERY HIGH",1.3,IF(V19="HIGH",1.18,1.08)),0) -> 410 | X19: =ROUND(Methodology!$B$11*IF(V19="VERY HIGH",1.45,IF(V19="HIGH",1.3,1.15)),0) -> 437 | Y19: Confirmed | Z19: Refined to 44,764 (2026 actual, was 44,857 estimate). | AA19: =TEXT(B19,"yyyy-mm") -> 2027-01
A20: WHX Dubai | B20: 46412 | C20: 46415 | D20: Dubai Exhibition Centre | E20: Expo City / DEC | F20: Healthcare | G20: 235000 | H20: 4300 | I20: 180+ countries (2026 actual); country pavilions incl. China, Germany, US, UK, Korea + first-time Slovakia/Thailand/Croatia | J20: 2026 actual benchmark (235,000+ professional visits, 4,300 exhibitors) | K20: 0.25 | L20: 0.4 | M20: 2 | N20: 3 | O20: 1.4 | P20: =IFERROR(ROUND(G20*K20*M20/O20,0),"") -> 83929 | Q20: =IFERROR(ROUND(G20*L20*N20/O20,0),"") -> 201429 | R20: 0.002 | S20: 0.006 | T20: =IFERROR(ROUND(P20*R20,0),"") -> 168 | U20: =IFERROR(ROUND(Q20*S20,0),"") -> 1209 | V20: VERY HIGH | W20: =ROUND(Methodology!$B$11*IF(V20="VERY HIGH",1.3,IF(V20="HIGH",1.18,1.08)),0) -> 494 | X20: =ROUND(Methodology!$B$11*IF(V20="VERY HIGH",1.45,IF(V20="HIGH",1.3,1.15)),0) -> 551 | Y20: Confirmed | Z20: CORRECTED — attendance updated from 90,000 (planning estimate) to 235,000 (Feb 2026 actual, incl. co-located WHX Labs/Medlab); major upward revision. | AA20: =TEXT(B20,"yyyy-mm") -> 2027-01
A21: WHX Labs Dubai | B21: 46413 | C21: 46416 | D21: DWTC | E21: DWTC | F21: Healthcare / Labs | G21: 25000 | H21: 1200 | I21: Co-located with WHX Dubai; similar international healthcare-professional profile | J21: Planning estimate | K21: 0.2 | L21: 0.35 | M21: 1.8 | N21: 2.5 | O21: 1.4 | P21: =IFERROR(ROUND(G21*K21*M21/O21,0),"") -> 6429 | Q21: =IFERROR(ROUND(G21*L21*N21/O21,0),"") -> 15625 | R21: 0.001 | S21: 0.004 | T21: =IFERROR(ROUND(P21*R21,0),"") -> 6 | U21: =IFERROR(ROUND(Q21*S21,0),"") -> 63 | V21: MEDIUM | W21: =ROUND(Methodology!$B$11*IF(V21="VERY HIGH",1.3,IF(V21="HIGH",1.18,1.08)),0) -> 410 | X21: =ROUND(Methodology!$B$11*IF(V21="VERY HIGH",1.45,IF(V21="HIGH",1.3,1.15)),0) -> 437 | Y21: Confirmed | AA21: =TEXT(B21,"yyyy-mm") -> 2027-01
A22: Gulfood | B22: 46461 | C22: 46465 | D22: DWTC + Dubai Exhibition Centre | E22: Expo City + DWTC | F22: F&B | G22: 300000 | H22: 8500 | I22: 195 countries (2026 actual benchmark) | J22: 2026 actual benchmark (300,000 visitors, 8,500+ exhibitors across DWTC + new Dubai Exhibition Centre / Expo City venue) | K22: 0.35 | L22: 0.5 | M22: 2.5 | N22: 3.5 | O22: 1.4 | P22: =IFERROR(ROUND(G22*K22*M22/O22,0),"") -> 187500 | Q22: =IFERROR(ROUND(G22*L22*N22/O22,0),"") -> 375000 | R22: 0.003 | S22: 0.008 | T22: =IFERROR(ROUND(P22*R22,0),"") -> 563 | U22: =IFERROR(ROUND(Q22*S22,0),"") -> 3000 | V22: VERY HIGH | W22: =ROUND(Methodology!$B$11*IF(V22="VERY HIGH",1.3,IF(V22="HIGH",1.18,1.08)),0) -> 494 | X22: =ROUND(Methodology!$B$11*IF(V22="VERY HIGH",1.45,IF(V22="HIGH",1.3,1.15)),0) -> 551 | Y22: Confirmed | Z22: CORRECTED — attendance filled in from blank to 300,000 (Jan 2026 actual, dual-venue record edition); Hotel Impact upgraded MEDIUM → VERY HIGH. | AA22: =TEXT(B22,"yyyy-mm") -> 2027-03
A23: Seamless Middle East | B23: 46508 | C23: 46538 | D23: DWTC (TBC) | E23: DWTC | F23: Fintech / Retail Tech | I23: Not published | J23: Dates TBC; depends on 2026 edition outcome (see Sep 2026 entry) | K23: 0.2 | L23: 0.35 | M23: 1.8 | N23: 2.5 | O23: 1.4 | R23: 0.001 | S23: 0.004 | T23: =IFERROR(ROUND(P23*R23,0),"") -> 0 | U23: =IFERROR(ROUND(Q23*S23,0),"") -> 0 | V23: MEDIUM | W23: =ROUND(Methodology!$B$11*IF(V23="VERY HIGH",1.3,IF(V23="HIGH",1.18,1.08)),0) -> 410 | X23: =ROUND(Methodology!$B$11*IF(V23="VERY HIGH",1.45,IF(V23="HIGH",1.3,1.15)),0) -> 437 | Y23: TBC / Benchmark | AA23: =TEXT(B23,"yyyy-mm") -> 2027-05
A24: Beautyworld Middle East | B24: 46661 | C24: 46691 | D24: DWTC (TBC) | E24: DWTC | F24: Beauty | G24: 85291 | H24: 1966 | I24: 178 countries (2025 benchmark); top markets UK, USA, France, India, Italy, Spain | J24: Dates TBC; 2025 actual benchmark | K24: 0.25 | L24: 0.4 | M24: 2 | N24: 3 | O24: 1.4 | P24: =IFERROR(ROUND(G24*K24*M24/O24,0),"") -> 30461 | Q24: =IFERROR(ROUND(G24*L24*N24/O24,0),"") -> 73107 | R24: 0.002 | S24: 0.007 | T24: =IFERROR(ROUND(P24*R24,0),"") -> 61 | U24: =IFERROR(ROUND(Q24*S24,0),"") -> 512 | V24: HIGH | W24: =ROUND(Methodology!$B$11*IF(V24="VERY HIGH",1.3,IF(V24="HIGH",1.18,1.08)),0) -> 448 | X24: =ROUND(Methodology!$B$11*IF(V24="VERY HIGH",1.45,IF(V24="HIGH",1.3,1.15)),0) -> 494 | Y24: TBC / Benchmark | Z24: CORRECTED — attendance updated from 71,439 to 85,291 (2025 actual). | AA24: =TEXT(B24,"yyyy-mm") -> 2027-10
A25: WETEX | B25: 46661 | C25: 46691 | D25: DWTC (TBC) | E25: DWTC | F25: Energy / Sustainability | G25: 50000 | H25: 3100 | I25: 65 countries (2025 benchmark) | J25: Dates/attendance TBC; 2025 actual benchmark | K25: 0.2 | L25: 0.35 | M25: 1.8 | N25: 2.5 | O25: 1.4 | P25: =IFERROR(ROUND(G25*K25*M25/O25,0),"") -> 12857 | Q25: =IFERROR(ROUND(G25*L25*N25/O25,0),"") -> 31250 | R25: 0.001 | S25: 0.004 | T25: =IFERROR(ROUND(P25*R25,0),"") -> 13 | U25: =IFERROR(ROUND(Q25*S25,0),"") -> 125 | V25: MEDIUM | W25: =ROUND(Methodology!$B$11*IF(V25="VERY HIGH",1.3,IF(V25="HIGH",1.18,1.08)),0) -> 410 | X25: =ROUND(Methodology!$B$11*IF(V25="VERY HIGH",1.45,IF(V25="HIGH",1.3,1.15)),0) -> 437 | Y25: TBC / Benchmark | Z25: CORRECTED — attendance updated from 35,000 to 50,000. | AA25: =TEXT(B25,"yyyy-mm") -> 2027-10
A26: Big 5 Global | B26: 46692 | C26: 46721 | D26: DWTC (TBC) | E26: DWTC | F26: Construction | G26: 85000 | H26: 2500 | I26: 150+ countries (2024 benchmark) | J26: Dates TBC; 2024 actual benchmark | K26: 0.25 | L26: 0.4 | M26: 2 | N26: 3 | O26: 1.4 | P26: =IFERROR(ROUND(G26*K26*M26/O26,0),"") -> 30357 | Q26: =IFERROR(ROUND(G26*L26*N26/O26,0),"") -> 72857 | R26: 0.002 | S26: 0.007 | T26: =IFERROR(ROUND(P26*R26,0),"") -> 61 | U26: =IFERROR(ROUND(Q26*S26,0),"") -> 510 | V26: HIGH | W26: =ROUND(Methodology!$B$11*IF(V26="VERY HIGH",1.3,IF(V26="HIGH",1.18,1.08)),0) -> 448 | X26: =ROUND(Methodology!$B$11*IF(V26="VERY HIGH",1.45,IF(V26="HIGH",1.3,1.15)),0) -> 494 | Y26: TBC / Benchmark | Z26: CORRECTED — attendance updated from 65,000 to 85,000. | AA26: =TEXT(B26,"yyyy-mm") -> 2027-11
A27: Dubai Airshow | B27: 46706 | C27: 46710 | D27: Dubai World Central | E27: DWC / Dubai South | F27: Aerospace | G27: 248788 | H27: 1500 | I27: 115 countries (2025 actual); 490 military/civil delegations | J27: 2025 actual benchmark (248,788 total visitors incl. public Skyview days, 1,500+ exhibitors) | K27: 0.35 | L27: 0.45 | M27: 2.5 | N27: 3.5 | O27: 1.4 | P27: =IFERROR(ROUND(G27*K27*M27/O27,0),"") -> 155493 | Q27: =IFERROR(ROUND(G27*L27*N27/O27,0),"") -> 279887 | R27: 0.005 | S27: 0.01 | T27: =IFERROR(ROUND(P27*R27,0),"") -> 777 | U27: =IFERROR(ROUND(Q27*S27,0),"") -> 2799 | V27: VERY HIGH | W27: =ROUND(Methodology!$B$11*IF(V27="VERY HIGH",1.3,IF(V27="HIGH",1.18,1.08)),0) -> 494 | X27: =ROUND(Methodology!$B$11*IF(V27="VERY HIGH",1.45,IF(V27="HIGH",1.3,1.15)),0) -> 551 | Y27: Confirmed | Z27: CORRECTED — attendance updated from 148,000 to 248,788 (2025 actual); major upward revision — closest major DWC demand driver to Lakeview. | AA27: =TEXT(B27,"yyyy-mm") -> 2027-11
A28: Automechanika Dubai | B28: 46692 | C28: 46721 | D28: Dubai Exhibition Centre (TBC) | E28: Expo City / DEC | F28: Automotive | G28: 50408 | H28: 2273 | I28: 162 countries (2025 benchmark); top markets Saudi Arabia, Iran, India, China, Iraq | J28: Dates TBC; 2025 actual benchmark | K28: 0.25 | L28: 0.4 | M28: 2 | N28: 3 | O28: 1.4 | P28: =IFERROR(ROUND(G28*K28*M28/O28,0),"") -> 18003 | Q28: =IFERROR(ROUND(G28*L28*N28/O28,0),"") -> 43207 | R28: 0.002 | S28: 0.007 | T28: =IFERROR(ROUND(P28*R28,0),"") -> 36 | U28: =IFERROR(ROUND(Q28*S28,0),"") -> 302 | V28: HIGH | W28: =ROUND(Methodology!$B$11*IF(V28="VERY HIGH",1.3,IF(V28="HIGH",1.18,1.08)),0) -> 448 | X28: =ROUND(Methodology!$B$11*IF(V28="VERY HIGH",1.45,IF(V28="HIGH",1.3,1.15)),0) -> 494 | Y28: TBC / Benchmark | AA28: =TEXT(B28,"yyyy-mm") -> 2027-11
A29: GITEX Global | B29: 46722 | C29: 46752 | D29: Dubai Exhibition Centre (TBC) | E29: Expo City / DEC | F29: Technology | G29: 200000 | H29: 6800 | I29: 180+ countries (2025 benchmark) | J29: Dates/attendance TBC; 2025 actual benchmark | K29: 0.25 | L29: 0.4 | M29: 2 | N29: 3 | O29: 1.4 | P29: =IFERROR(ROUND(G29*K29*M29/O29,0),"") -> 71429 | Q29: =IFERROR(ROUND(G29*L29*N29/O29,0),"") -> 171429 | R29: 0.002 | S29: 0.006 | T29: =IFERROR(ROUND(P29*R29,0),"") -> 143 | U29: =IFERROR(ROUND(Q29*S29,0),"") -> 1029 | V29: VERY HIGH | W29: =ROUND(Methodology!$B$11*IF(V29="VERY HIGH",1.3,IF(V29="HIGH",1.18,1.08)),0) -> 494 | X29: =ROUND(Methodology!$B$11*IF(V29="VERY HIGH",1.45,IF(V29="HIGH",1.3,1.15)),0) -> 551 | Y29: TBC / Benchmark | Z29: CORRECTED — attendance updated from 100,000 to 200,000. | AA29: =TEXT(B29,"yyyy-mm") -> 2027-12

Sheet Monthly Summary
A1: Month | B1: Events | C1: Market Room Nights Low | D1: Market Room Nights High | E1: Lakeview Room Nights Low | F1: Lakeview Room Nights High | G1: Key Drivers | H1: RM Action
A2: 2026-09 | B2: =COUNTIF('Event Calendar'!$AA$2:$AA$29,A2) -> 6 | C2: =SUMIF('Event Calendar'!$AA$2:$AA$29,A2,'Event Calendar'!$P$2:$P$29) -> 83036 | D2: =SUMIF('Event Calendar'!$AA$2:$AA$29,A2,'Event Calendar'!$Q$2:$Q$29) -> 172411 | E2: =SUMIF('Event Calendar'!$AA$2:$AA$29,A2,'Event Calendar'!$T$2:$T$29) -> 149 | F2: =SUMIF('Event Calendar'!$AA$2:$AA$29,A2,'Event Calendar'!$U$2:$U$29) -> 1107 | G2: Arabian Travel Market, Middle East Energy, Dubai Derma, GISEC Global | H2: Six confirmed international trade shows in one month (incl. 3 newly added — ATM, Middle East Energy, Dubai Derma). Protect event-night rates; target exhibitors/delegations for DEC and DWTC events.
A3: 2026-10 | B3: =COUNTIF('Event Calendar'!$AA$2:$AA$29,A3) -> 7 | C3: =SUMIF('Event Calendar'!$AA$2:$AA$29,A3,'Event Calendar'!$P$2:$P$29) -> 69546 | D3: =SUMIF('Event Calendar'!$AA$2:$AA$29,A3,'Event Calendar'!$Q$2:$Q$29) -> 168107 | E3: =SUMIF('Event Calendar'!$AA$2:$AA$29,A3,'Event Calendar'!$T$2:$T$29) -> 121 | F3: =SUMIF('Event Calendar'!$AA$2:$AA$29,A3,'Event Calendar'!$U$2:$U$29) -> 1097 | G3: Beautyworld Dubai, Dubai Muscle Show / Active Show | H3: Protect ADR and build 2–4 night event packages; monitor overlapping shows.
A4: 2026-11 | B4: =COUNTIF('Event Calendar'!$AA$2:$AA$29,A4) -> 3 | C4: =SUMIF('Event Calendar'!$AA$2:$AA$29,A4,'Event Calendar'!$P$2:$P$29) -> 87052 | D4: =SUMIF('Event Calendar'!$AA$2:$AA$29,A4,'Event Calendar'!$Q$2:$Q$29) -> 193448 | E4: =SUMIF('Event Calendar'!$AA$2:$AA$29,A4,'Event Calendar'!$T$2:$T$29) -> 213 | F4: =SUMIF('Event Calendar'!$AA$2:$AA$29,A4,'Event Calendar'!$U$2:$U$29) -> 1431 | G4: Gulfood Manufacturing, Automechanika Dubai, Big 5 Global | H4: Peak compression month; restrict discounts around Automechanika/Big 5.
A5: 2026-12 | B5: =COUNTIF('Event Calendar'!$AA$2:$AA$29,A5) -> 1 | C5: =SUMIF('Event Calendar'!$AA$2:$AA$29,A5,'Event Calendar'!$P$2:$P$29) -> 71429 | D5: =SUMIF('Event Calendar'!$AA$2:$AA$29,A5,'Event Calendar'!$Q$2:$Q$29) -> 171429 | E5: =SUMIF('Event Calendar'!$AA$2:$AA$29,A5,'Event Calendar'!$T$2:$T$29) -> 143 | F5: =SUMIF('Event Calendar'!$AA$2:$AA$29,A5,'Event Calendar'!$U$2:$U$29) -> 1029 | G5: GITEX Global (attendance corrected to 200,000 actual benchmark) | H5: Protect GITEX dates; target international tech exhibitors and delegations — demand materially higher than previously modelled.
A6: 2027-01 | B6: =COUNTIF('Event Calendar'!$AA$2:$AA$29,A6) -> 3 | C6: =SUMIF('Event Calendar'!$AA$2:$AA$29,A6,'Event Calendar'!$P$2:$P$29) -> 101869 | D6: =SUMIF('Event Calendar'!$AA$2:$AA$29,A6,'Event Calendar'!$Q$2:$Q$29) -> 245032 | E6: =SUMIF('Event Calendar'!$AA$2:$AA$29,A6,'Event Calendar'!$T$2:$T$29) -> 186 | F6: =SUMIF('Event Calendar'!$AA$2:$AA$29,A6,'Event Calendar'!$U$2:$U$29) -> 1384 | G6: WHX Dubai (attendance corrected to 235,000 actual benchmark), Intersec Global | H6: Target healthcare/security exhibitors; maximise ADR around WHX/Intersec — WHX is now the #3 demand driver in the calendar.
A7: 2027-03 | B7: =COUNTIF('Event Calendar'!$AA$2:$AA$29,A7) -> 1 | C7: =SUMIF('Event Calendar'!$AA$2:$AA$29,A7,'Event Calendar'!$P$2:$P$29) -> 187500 | D7: =SUMIF('Event Calendar'!$AA$2:$AA$29,A7,'Event Calendar'!$Q$2:$Q$29) -> 375000 | E7: =SUMIF('Event Calendar'!$AA$2:$AA$29,A7,'Event Calendar'!$T$2:$T$29) -> 563 | F7: =SUMIF('Event Calendar'!$AA$2:$AA$29,A7,'Event Calendar'!$U$2:$U$29) -> 3000 | G7: Gulfood (attendance filled in — 300,000 actual 2026 benchmark; now the single largest demand driver in this calendar) | H7: Gulfood is now the single largest compression period in this calendar (dual-venue, 300k actual 2026 benchmark); start sales 90–120 days out and protect BAR aggressively.
A8: 2027-05 | B8: =COUNTIF('Event Calendar'!$AA$2:$AA$29,A8) -> 1 | C8: =SUMIF('Event Calendar'!$AA$2:$AA$29,A8,'Event Calendar'!$P$2:$P$29) -> 0 | D8: =SUMIF('Event Calendar'!$AA$2:$AA$29,A8,'Event Calendar'!$Q$2:$Q$29) -> 0 | E8: =SUMIF('Event Calendar'!$AA$2:$AA$29,A8,'Event Calendar'!$T$2:$T$29) -> 0 | F8: =SUMIF('Event Calendar'!$AA$2:$AA$29,A8,'Event Calendar'!$U$2:$U$29) -> 0 | H8: Monitor Seamless date release and open targeted tech/corporate offers.
A9: 2027-10 | B9: =COUNTIF('Event Calendar'!$AA$2:$AA$29,A9) -> 2 | C9: =SUMIF('Event Calendar'!$AA$2:$AA$29,A9,'Event Calendar'!$P$2:$P$29) -> 43318 | D9: =SUMIF('Event Calendar'!$AA$2:$AA$29,A9,'Event Calendar'!$Q$2:$Q$29) -> 104357 | E9: =SUMIF('Event Calendar'!$AA$2:$AA$29,A9,'Event Calendar'!$T$2:$T$29) -> 74 | F9: =SUMIF('Event Calendar'!$AA$2:$AA$29,A9,'Event Calendar'!$U$2:$U$29) -> 637 | G9: Beautyworld Middle East | H9: Monitor Beautyworld/WETEX confirmation; build shoulder-night packages.
A10: 2027-11 | B10: =COUNTIF('Event Calendar'!$AA$2:$AA$29,A10) -> 3 | C10: =SUMIF('Event Calendar'!$AA$2:$AA$29,A10,'Event Calendar'!$P$2:$P$29) -> 203853 | D10: =SUMIF('Event Calendar'!$AA$2:$AA$29,A10,'Event Calendar'!$Q$2:$Q$29) -> 395951 | E10: =SUMIF('Event Calendar'!$AA$2:$AA$29,A10,'Event Calendar'!$T$2:$T$29) -> 874 | F10: =SUMIF('Event Calendar'!$AA$2:$AA$29,A10,'Event Calendar'!$U$2:$U$29) -> 3611 | G10: Big 5 Global, Dubai Airshow (attendance corrected to 248,788 actual benchmark), Automechanika Dubai | H10: Critical month: Dubai Airshow demand corrected sharply upward (now ~2nd-largest driver after Gulfood) — maximise ADR and restrict discounting city-wide.
A11: 2027-12 | B11: =COUNTIF('Event Calendar'!$AA$2:$AA$29,A11) -> 1 | C11: =SUMIF('Event Calendar'!$AA$2:$AA$29,A11,'Event Calendar'!$P$2:$P$29) -> 71429 | D11: =SUMIF('Event Calendar'!$AA$2:$AA$29,A11,'Event Calendar'!$Q$2:$Q$29) -> 171429 | E11: =SUMIF('Event Calendar'!$AA$2:$AA$29,A11,'Event Calendar'!$T$2:$T$29) -> 143 | F11: =SUMIF('Event Calendar'!$AA$2:$AA$29,A11,'Event Calendar'!$U$2:$U$29) -> 1029 | G11: GITEX Global | H11: Monitor GITEX confirmation; protect year-end tech demand.

Sheet Methodology
A1: Purpose | B1: DIP / Green Community hotel-impact calendar for Millennium Lakeview, Sep 2026–Dec 2027.
A2: Priority geography | B2: Primary: Dubai Exhibition Centre / Expo City and Dubai World Central (DWC/Dubai South). Secondary: DWTC, where mega-events can create citywide compression.
A3: Total attendance | B3: Published attendance where available; otherwise a planning estimate or prior-edition benchmark. Attendance is not hotel demand.
A4: Market room nights | B4: Total attendance × out-of-town share × average stay nights ÷ persons per room.
A5: Out-of-town assumptions | B5: Generally 20–40%; higher for international mega-events. Dubai Airshow 35–45%; Gulfood 35–50%.
A6: Persons per room | B6: 1.4 used as a planning assumption for mixed business-event demand.
A7: Lakeview capture | B7: Illustrative property capture assumption of 0.1–1.0%, adjusted upward for DWC/DEC proximity and event scale.
A8: Important | B8: Lakeview room-night figures are planning ranges, not organizer forecasts. Replace with actual pickup/pace once booking data is available.
A9: RM use | B9: Use event dates as compression flags; compare OTB/pickup, protect BAR/ADR on peak nights, and prospect exhibitors/delegations 60–120 days ahead.
A10: 2027 caution | B10: Several 2027 dates are not yet published. Those rows are marked TBC / Benchmark and should be updated as organizers release dates.
A11: DIP/Green Community Base ADR (AED) | B11: 380
A12: ADR uplift model | B12: DIP Area ADR Low/High = Base ADR × uplift factor by Hotel Impact tier — MEDIUM ×1.08/×1.15, HIGH ×1.18/×1.30, VERY HIGH ×1.30/×1.45. Base ADR of AED 380 is an illustrative planning assumption for the DIP/Green Community 3–4★ competitive set — replace with Millennium Lakeview's actual STR/competitive-set ADR data once available.
A13: Primary Source Markets / countries | B13: Country counts and top feeder markets are drawn from organiser post-show reports and press releases where published (see Source Log). Where no breakdown is published, the cell is marked 'Not published' rather than estimated, to avoid fabricating attendee data.
A14: Citywide vs Lakeview figures | B14: 'Market Room Nights' = total out-of-town, citywide hotel-night demand generated by an event (all competing hotels, not just Lakeview). 'Lakeview Room Nights' = Market Room Nights × an illustrative capture-rate assumption for this single property. Earlier drafts of this workbook (Hotel Impact Events / High-Impact Hotel Demand Calendar / Highest ADR tabs) had mislabelled citywide market demand as 'Impact on MLVH' — this has been corrected (see those tabs).
A15: 2026 corrections applied | B15: GITEX Global, Big 5 Global, Beautyworld Dubai/ME, WETEX, Dubai Airshow, Gulfood and WHX Dubai attendance figures were updated to the latest published actual/benchmark editions (several 2026 editions had already concluded as of this review — Gulfood Jan 2026, WHX Dubai Feb 2026, Dubai Airshow Nov 2025). Arabian Travel Market, Middle East Energy, Dubai Derma and Seamless Middle East (Sep 2026) were added — they were present in the 'Key Demand Drivers for DIP' research tab but had been omitted from the quantitative Event Calendar model.

Sheet Source Log
A1: Source | B1: URL | C1: Purpose
A2: Dubai Exhibition Centre | B2: https://www.dubaiexhibitioncentre.com/en/whats-on | C2: DEC event calendar
A3: DWTC | B3: https://www.dwtc.com/en/events/ | C3: DWTC event calendar
A4: DWTC Q4 2026 | B4: https://www.dwtc.com/en/press/dwtc-announces-diverse-events-calendar-across-two-venues-through-year-end-2026/ | C4: 2026 dates across DWTC and DEC
A5: Automechanika Dubai | B5: https://automechanika-dubai.ae/dubai/en/press/press-releases/all/14052026.html | C5: 2026 date and prior attendance/exhibitor benchmark
A6: Dubai Muscle Show | B6: https://dubaimuscleshow.com/ | C6: 2026 date and attendance
A7: Big 5 Global | B7: https://www.big5global.com/event/event-at-a-glance/ | C7: 2026 date and attendance/exhibitor information
A8: WHX Dubai | B8: https://www.dubaiexhibitioncentre.com/en/whats-on/whx-dubai-2027 | C8: 2027 date and expected attendance/exhibitors
A9: Gulfood 2027 | B9: https://www.gulfood.com/exhibit-gulfood | C9: 2027 date
A10: Intersec Global | B10: https://intersecglobal.ae.messefrankfurt.com/dubai/en/about.html | C10: 2027 date and benchmark attendance/exhibitors
A11: Dubai Airshow | B11: https://www.dubaiairshow.aero/ | C11: 2027 date and attendance/exhibitor benchmark
A12: GITEX | B12: https://www.gitex.com/ | C12: 2026 date and venue
... A27: Seamless Middle East 2026 — date conflict | B27: https://events.coinpedia.org/seamless-middle-east-2026-8120/ | https://ilikevents.com/event/10238-seamless-middle-east | C27: Sources disagree: 22–24 Sep 2026 (rebrand) vs 12–14 May 2026 — flagged for organiser verification

Sheet Key Demand Drivers for DIP
A1: 46266
A2: NOTE: This tab is the broader research 'watch list' behind the calendar. Events with a published, sourced attendance figure have been promoted into the quantitative 'Event Calendar' master tab (Middle East Energy, Dubai Derma, Arabian Travel Market and Seamless Middle East were added from this list on review). Remaining rows here lack a quantified attendance figure and are kept as monitoring items rather than being modelled, to avoid fabricating numbers.
A5: Event | B5: Dates | C5: Venue | D5: Stated Attendance | E5: Hotel-Night Demand Indicators
A6: Middle East Energy | B6: Sep 1–3 | C6: DWTC | D6: 35,000 attendees, 1,900 exhibitors, 250 speakers, 150+ countries | E6: High out-of-town; major energy sector trade show
A7: Experiential Planner Expo | B7: Sep 2–3 | C7: Dubai | D7: MICE sector event; planners, buyers, suppliers | E7: Moderate; industry-specific
A8: International Property Show (IPS) | B8: Sep 7–9 | C8: DWTC | D8: Developers, investors, banks, legal firms | E8: Moderate-High; regional investor base
A9: AIM Congress | B9: Sep 7–9 | C9: DWTC | D9: Global investors, policymakers, business leaders | E9: High out-of-town; investment-focused
A10: Dubai Derma | B10: Sep 8–10 | C10: DWTC | D10: 25,000+ visitors, 500+ speakers, 1,875 brands, 114 countries | E10: High out-of-town; medical professionals
A11: Crypto Expo | B11: Sep 9–10 | C11: Dubai | D11: 7,000+ attendees, 100 exhibitors, 140 speakers, 40+ countries | E11: High out-of-town concentration
A12: Arabian Travel Market (ATM) | B12: Sep 14–17 | C12: DWTC | D12: Destinations, airlines, hotels, tech providers; theme: Travel 2040 | E12: High; major travel trade show
A13: Arab Media Summit | B13: Sep 15–17 | C13: Dubai | D13: 200+ media figures outside UAE, 10,000 regional professionals | E13: Moderate-High; regional draw
A14: GISEC Global | B14: Sep 16–18 | C14: DEC, Expo City | D14: 25,000+ professionals, 182+ countries, 350 leaders, 750 brands | E14: High out-of-town; cybersecurity sector
A15: MEBIS (Banking Innovation) | B15: Sep 16–17 | C15: Jumeirah Emirates Towers | D15: Senior banking executives, tech specialists | E15: Moderate; DIFC-adjacent
A16: The Forex Expo | B16: Sep 22–23 | C16: Dubai | D16: Brokers, traders, tech providers, financial institutions | E16: Moderate-High; international trading community
... A22: AWS Summit Dubai | B22: Sep (exact date TBC) | C22: Dubai | D22: Cloud computing, AI/ML keynotes | E22: Moderate; regional tech community
A25: 46296
A27: Event | B27: Dates | C27: Venue | D27: Stated Attendance | E27: Hotel-Night Demand Indicators
A28: Future Hospitality Summit | B28: Sep 29–Oct 1 | C28: Dubai | D28: Hotel operators, investors, developers, tourism executives | E28: High; hospitality investment focus
A29: Beautyworld Dubai | B29: Oct 6–8 | C29: DWTC | D29: Beauty/personal care trade show | E29: Moderate-High; regional trade buyers
A30: Airport Show & Global Airport Leaders Forum | B30: Oct 12–14 | C30: DWTC | D30: Aviation industry professionals | E30: Moderate; specialized sector
A31: RISE Global Real Estate Investment Summit | B31: Oct 13–14 | C31: DWTC | D31: Real estate investors, developers | E31: Moderate-High
A32: WETEX | B32: Oct 20–22 | C32: DWTC | D32: Water, energy, technology, environment exhibition | E32: High; large regional trade show
A33: World Green Economy Summit | B33: Oct 21–22 | C33: DWTC | D33: Sustainability leaders, policymakers | E33: Moderate
A34: Dubai AI Festival | B34: Oct 26–27 | C34: DWTC | D34: AI industry professionals, researchers | E34: Moderate-High; growing sector
A35: GITEX Global / GITEX TechCation (early activations) | B35: Building toward Dec | C35: Expo City | D35: Preparatory and promotional events | E35: Monitor
A37: 46327
A38: Event | B38: Dates | C38: Venue | D38: Stated Attendance | E38: Hotel-Night Demand Indicators
A39: Dubai Future Finance Week / Dubai FinTech Summit | B39: Nov 2–6 | C39: DIFC & across Dubai | D39: 850+ speakers, 85+ events, 12 signature forums, 14 stages | E39: Very High; region's largest finance gathering; global decision-makers
A40: Gulf Host | B40: Nov 3–5 | C40: DWTC | D40: Hospitality equipment, foodservice | E40: Moderate-High
A41: Gulfood Manufacturing | B41: Nov 3–5 | C41: DWTC | D41: Food processing/manufacturing | E41: High out-of-town; global food industry
A42: ISM Middle East | B42: Nov 3–5 | C42: DWTC | D42: Sweets & snacks trade show | E42: Moderate-High
A43: Private Label Middle East | B43: Nov 3–5 | C43: DWTC | D43: Private label products | E43: Moderate
A44: Automechanika Dubai | B44: Nov 10–12 | C44: DEC, Expo City | D44: Region's largest automotive aftermarket event | E44: High out-of-town
A45: GESS | B45: Nov 10–12 | C45: DWTC | D45: Education supplies/technology | E45: Moderate
A46: EV World Show | B46: Nov 10–12 | C46: DWTC | D46: Electric vehicle industry | E46: Moderate-High; growing sector
A47: World Vape Show | B47: Nov 10–12 | C47: DWTC | D47: Vaping industry trade show | E47: Moderate
A48: World Art Dubai | B48: Nov 19–22 | C48: DEC, Expo City | D48: Art fair; regional/international galleries | E48: Moderate; collector/visitor demand
A49: Big 5 Global | B49: Nov 23–26 | C49: DWTC | D49: Construction industry; co-located with GeoWorld, HVACR World, LiveableCitiesX, Future FM | E49: High; major global construction event
A50: Onset Expo | B50: Nov 20–22 | C50: DEC, Expo City | E50: Low-Moderate; verify sector
A53: 46357
...

Sheet Hotel Impact Events
J10: Annual recurring demand patterns (reference — not tied to a specific dated row)
A15: Quick reference — 2026 confirmed DIP / DEC events (pulled from Event Calendar master)
A17: Month | B17: Event | C17: Venue / Area | D17: Occupancy impact | E17: ADR opportunity | J17: Event / period | K17: Typical location (approx.) | L17: Why it drives demand | M17: Likely hotel impact near DIP / Green Community
A18: 46266 | B18: GISEC Global (16–18 Sep) | C18: Expo City / DEC | D18: High | E18: High | J18: Gulfood (annual, late Jan–Feb) | K18: DWTC + Dubai Exhibition Centre (Expo City) | L18: Very large international trade show; strong corporate travel | M18: High occupancy • good ADR especially midweek
A19: 46266 | B19: Middle East Coatings Show (28–30 Sep) | C19: Expo City / DEC | D19: Medium | E19: Medium | J19: Dubai Marathon / peak winter sports weekends (annual, Jan) | K19: City-wide | L19: Leisure + participants + spectators | M19: Medium occupancy, limited ADR unless paired with other events
A20: 46296 | B20: CABSAT + SAT Expo (5–7 Oct) | C20: Expo City / DEC | D20: High | E20: High | J20: DIHAD / emergency & humanitarian events (often Aug) | K20: DWTC/DEC | L20: International delegates, exhibitors | M20: Medium–high occupancy, medium ADR
A21: 46327 | B21: Automechanika Dubai (10–12 Nov) | C21: Expo City / DEC | D21: High | E21: High | J21: GITEX Global (annual, autumn) | K21: Dubai Exhibition Centre (Expo City) | L21: Major tech week; many corporate visitors | M21: High occupancy • high ADR
A22: 46357 | B22: GITEX Global (8–11 Dec) | C22: Expo City / DEC | D22: Very High | E22: Very High | J22: Arabian Travel Market (annual, typically May) | K22: DWTC | L22: Large travel trade show | M22: High occupancy • good ADR
A23: 46388 | B23: Michelin 24H Dubai (8–10 Jan) | C23: Dubai Autodrome | D23: High | E23: Medium | J23: Middle East Energy (annual, typically Mar–Apr) | K23: DWTC | L23: Large B2B expo | M23: Medium–high occupancy • medium ADR
J24: City-wide peak leisure periods (Eid breaks, Dec/NY, school holidays) | K24: City-wide | L24: Leisure travel spike | M24: High occupancy, ADR depends on competitive set and restrictions
J25: Large MICE weeks at Expo City / DEC (multi-event clusters) | K25: Expo City / DEC | L25: Co-located events create compressed demand | M25: High occupancy, good ADR if inventory tight

Sheet High-Impact Hotel Demand Calend
A1: Event | B1: Dates | C1: Venue | D1: Total Attendance* | E1: Citywide Market Room-Night Demand (Out-of-Town) | F1: Lakeview Potential Room Nights | G1: Hotel Impact
A2: Middle East Energy | B2: 1–3 Sep 2026 | C2: Dubai World Trade Centre | D2: 45,000 | E2: 19,286–43,393 | F2: 39–304 | G2: HIGH
A3: Dubai Derma | B3: 8–10 Sep 2026 | C3: Dubai World Trade Centre | D3: 25,000 | E3: 10,714–24,107 | F3: 11–96 | G3: HIGH
A4: Arabian Travel Market | B4: 14–17 Sep 2026 | C4: Dubai World Trade Centre | D4: 50,000 | E4: 40,179–75,000 | F4: 80–525 | G4: HIGH
A5: GISEC Global | B5: 16–18 Sep 2026 | C5: Dubai Exhibition Centre | D5: 15,000 | E5: 3,857–9,375 | F5: 8–75 | G5: MEDIUM
A6: Seamless Middle East (2026) | B6: 22–24 Sep 2026 | C6: Dubai World Trade Centre | D6: 20,000 | E6: 6,429–14,286 | F6: 6–57 | G6: MEDIUM
A7: Middle East Coatings Show | B7: 28–30 Sep 2026 | C7: Dubai Exhibition Centre | D7: 10,000 | E7: 2,571–6,250 | F7: 5–50 | G7: MEDIUM
A8: CABSAT + SAT Expo | B8: 5–7 Oct 2026 | C8: Dubai Exhibition Centre | D8: 15,000 | E8: 3,857–9,375 | F8: 8–75 | G8: MEDIUM
A9: Beautyworld Dubai | B9: 6–8 Oct 2026 | C9: DWTC | D9: 85,291 | E9: 30,461–73,107 | F9: 61–512 | G9: HIGH
A10: Airport Show + Global Airport Leaders Forum | B10: 12–14 Oct 2026 | C10: DWTC | D10: 20,000 | E10: 5,143–12,500 | F10: 5–50 | G10: MEDIUM
A11: WETEX | B11: 20–22 Oct 2026 | C11: DWTC | D11: 50,000 | E11: 12,857–31,250 | F11: 13–125 | G11: MEDIUM
A12: Baby & Kids Expo | B12: 22–24 Oct 2026 | C12: Dubai Exhibition Centre | D12: 12,000 | E12: 3,086–7,500 | F12: 6–60 | G12: MEDIUM
... A29: GITEX Global | B29: Dec 2027 (TBC) | C29: Dubai Exhibition Centre (TBC) | D29: 200,000 | E29: 71,429–171,429 | F29: 143–1,029 | G29: VERY HIGH
A30: * Column 5 is CITYWIDE out-of-town room-night demand (all competing hotels), not demand captured by Millennium Lakeview alone — this corrects the previous version of this tab, which mislabelled the citywide figure as 'Impact on MLVH'. See column 6 for the property-specific planning estimate, and the Methodology tab for the capture-rate assumptions behind it.

Sheet Highest ADR
A1: Highest Compression / ADR-Opportunity Dates for Millennium Lakeview
A3: Ranked by citywide out-of-town room-night demand near Green Community / DIP — recalculated from the corrected Event Calendar master.
A5: Rank | B5: Event | C5: Dates | D5: Citywide Room-Night Demand (Out-of-Town) | E5: Lakeview Potential Room Nights
A6: 1 | B6: Gulfood | C6: 15–19 Mar 2027 | D6: 187,500–375,000 | E6: 562–3,000
A7: 2 | B7: Dubai Airshow | C7: 15–19 Nov 2027 | D7: 155,492–279,887 | E7: 777–2,799
A8: 3 | B8: WHX Dubai | C8: 25–28 Jan 2027 | D8: 83,929–201,429 | E8: 168–1,209
A9: 4 | B9: GITEX Global | C9: 7–11 Dec 2026 | D9: 71,429–171,429 | E9: 143–1,029
A10: 5 | B10: GITEX Global | C10: Dec 2027 (TBC) | D10: 71,429–171,429 | E10: 143–1,029
A11: 6 | B11: Gulfood Manufacturing | C11: 3–5 Nov 2026 | D11: 38,692–77,384 | E11: 116–619
A12: 7 | B12: Arabian Travel Market | C12: 14–17 Sep 2026 | D12: 40,179–75,000 | E12: 80–525
A13: 8 | B13: Beautyworld Dubai | C13: 6–8 Oct 2026 | D13: 30,461–73,107 | E13: 61–512
A14: 9 | B14: Beautyworld Middle East | C14: Oct 2027 (TBC) | D14: 30,461–73,107 | E14: 61–512
A15: 10 | B15: Big 5 Global | C15: 23–26 Nov 2026 | D15: 30,357–72,857 | E15: 61–510

Sheet Events Calendar (Print)
A1: MILLENNIUM LAKEVIEW HOTEL
A2: Event Demand & ADR Calendar
A3: September 2026 – December 2027 | DIP · Green Community · Expo City Impact Zone
A5: Hotel Impact: | B5: MEDIUM | C5: HIGH | D5: VERY HIGH | F5: Figures are citywide/property planning estimates — see Methodology tab. Verify TBC dates before blocking inventory.
A7: SEPTEMBER 2026
A8: Dates | B8: Event | C8: Venue / Area | D8: Total Attendance | E8: Top Source Markets | F8: Market Room-Nights (Out-of-Town) | G8: Lakeview Potential Room-Nights | H8: DIP Area ADR (AED) | I8: Hotel Impact
A9: 1–3 Sep 2026 | B9: Middle East Energy | C9: DWTC | D9: 45,000 | E9: 131+ countries confirmed (2026); top international markets Nigeria, Egypt, Saudi Arabia | F9: 19,286–43,393 | G9: 39–304 | H9: AED 448–494 | I9: HIGH
A10: 8–10 Sep 2026 | B10: Dubai Derma | C10: DWTC | D10: 25,000 | E10: 114 countries; strong MENA / Asia / Europe medical-professional draw | F10: 10,714–24,107 | G10: 11–96 | H10: AED 448–494 | I10: HIGH
A11: 14–17 Sep 2026 | B11: Arabian Travel Market | C11: DWTC | D11: 50,000 | E11: 166 countries (2025 actual); top international markets India, Egypt, UK, Türkiye, USA | F11: 40,179–75,000 | G11: 80–525 | H11: AED 448–494 | I11: HIGH
A12: 16–18 Sep 2026 | B12: GISEC Global | C12: Expo City / DEC | D12: 15,000 | E12: 182+ countries (2026 projection) | F12: 3,857–9,375 | G12: 8–75 | H12: AED 410–437 | I12: MEDIUM
A13: 22–24 Sep 2026 | B13: Seamless Middle East (2026) | C13: DWTC | D13: 20,000 | E13: Not published for this edition | F13: 6,429–14,286 | G13: 6–57 | H13: AED 410–437 | I13: MEDIUM
A14: 28–30 Sep 2026 | B14: Middle East Coatings Show | C14: Expo City / DEC | D14: 10,000 | E14: 24+ countries | F14: 2,571–6,250 | G14: 5–50 | H14: AED 410–437 | I14: MEDIUM
A15: OCTOBER 2026
A16: Dates | B16: Event | C16: Venue / Area | D16: Total Attendance | E16: Top Source Markets | F16: Market Room-Nights (Out-of-Town) | G16: Lakeview Potential Room-Nights | H16: DIP Area ADR (AED) | I16: Hotel Impact
A17: 5–7 Oct 2026 | B17: CABSAT + SAT Expo | C17: Expo City / DEC | D17: 15,000 | E17: Not published | F17: 3,857–9,375 | G17: 8–75 | H17: AED 410–437 | I17: MEDIUM
A18: 6–8 Oct 2026 | B18: Beautyworld Dubai | C18: DWTC | D18: 85,291 | E18: 178 countries (2025 actual); top international markets UK, USA, France, India, Italy, Spain | F18: 30,461–73,107 | G18: 61–512 | H18: AED 448–494 | I18: HIGH
A19: 12–14 Oct 2026 | B19: Airport Show + Global Airport Leaders Forum | C19: DWTC | D19: 20,000 | E19: Not published | F19: 5,143–12,500 | G19: 5–50 | H19: AED 410–437 | I19: MEDIUM
A20: 20–22 Oct 2026 | B20: WETEX | C20: DWTC | D20: 50,000 | E20: 65 countries; 18 country pavilions; DEWA-led international energy/utility delegations | F20: 12,857–31,250 | G20: 13–125 | H20: AED 410–437 | I20: MEDIUM
A21: 22–24 Oct 2026 | B21: Baby & Kids Expo | C21: Expo City / DEC | D21: 12,000 | E21: Predominantly GCC / regional consumer visitors | F21: 3,086–7,500 | G21: 6–60 | H21: AED 410–437 | I21: MEDIUM
A22: 27–29 Oct 2026 | B22: Jewellery, Gem & Technology in Dubai | C22: Expo City / DEC | D22: 10,000 | E22: Not published | F22: 2,571–6,250 | G22: 5–50 | H22: AED 410–437 | I22: MEDIUM
A23: 30 Oct–01 Nov 2026 | B23: Dubai Muscle Show / Active Show | C23: Expo City / DEC | D23: 45,000 | E23: Predominantly GCC / regional fitness community; growing international athlete draw | F23: 11,571–28,125 | G23: 23–225 | H23: AED 448–494 | I23: HIGH
A24: NOVEMBER 2026
A25: Dates | B25: Event | C25: Venue / Area | D25: Total Attendance | E25: Top Source Markets | F25: Market Room-Nights (Out-of-Town) | G25: Lakeview Potential Room-Nights | H25: DIP Area ADR (AED) | I25: Hotel Impact
A26: 3–5 Nov 2026 | B26: Gulfood Manufacturing | C26: DWTC | D26: 61,907 | E26: Global F&B processing / manufacturing buyers — GCC, Africa, South Asia, Europe (detailed breakdown not published) | F26: 38,692–77,384 | G26: 116–619 | H26: AED 448–494 | I26: HIGH
A27: 10–12 Nov 2026 | B27: Automechanika Dubai | C27: Expo City / DEC | D27: 50,408 | E27: 162 countries (2025 actual); top markets Saudi Arabia, Iran, India, China, Iraq | F27: 18,003–43,207 | G27: 36–302 | H27: AED 448–494 | I27: HIGH
A28: 23–26 Nov 2026 | B28: Big 5 Global | C28: DWTC | D28: 85,000 | E28: 150+ countries (2024 actual); top markets UAE, Saudi Arabia, Turkey, Italy, China, India, Germany, USA | F28: 30,357–72,857 | G28: 61–510 | H28: AED 448–494 | I28: HIGH
A29: DECEMBER 2026
A30: Dates | B30: Event | C30: Venue / Area | D30: Total Attendance | E30: Top Source Markets | F30: Market Room-Nights (Out-of-Town) | G30: Lakeview Potential Room-Nights | H30: DIP Area ADR (AED) | I30: Hotel Impact
A31: 7–11 Dec 2026 | B31: GITEX Global | C31: Expo City / DEC | D31: 200,000 | E31: 180+ countries (2025); major delegations incl. India, Pakistan, Saudi Arabia, Egypt, UK, USA, China; 2025 Country Partner: Brazil | F31: 71,429–171,429 | G31: 143–1,029 | H31: AED 494–551 | I31: VERY HIGH
A32: JANUARY 2027
A33: Dates | B33: Event | C33: Venue / Area | D33: Total Attendance | E33: Top Source Markets | F33: Market Room-Nights (Out-of-Town) | G33: Lakeview Potential Room-Nights | H33: DIP Area ADR (AED) | I33: Hotel Impact
A34: 12–14 Jan 2027 | B34: Intersec Global | C34: DWTC | D34: 44,764 | E34: 151 countries (2026 actual); 60% domestic / 40% international; key markets USA, China, India, South Korea, France, Germany, Italy, Türkiye, UK | F34: 11,511–27,978 | G34: 12–112 | H34: AED 410–437 | I34: MEDIUM
A35: 25–28 Jan 2027 | B35: WHX Dubai | C35: Expo City / DEC | D35: 235,000 | E35: 180+ countries (2026 actual); country pavilions incl. China, Germany, US, UK, Korea + first-time Slovakia/Thailand/Croatia | F35: 83,929–201,429 | G35: 168–1,209 | H35: AED 494–551 | I35: VERY HIGH
A36: 26–29 Jan 2027 | B36: WHX Labs Dubai | C36: DWTC | D36: 25,000 | E36: Co-located with WHX Dubai; similar international healthcare-professional profile | F36: 6,429–15,625 | G36: 6–62 | H36: AED 410–437 | I36: MEDIUM
A37: MARCH 2027
A38: Dates | B38: Event | C38: Venue / Area | D38: Total Attendance | E38: Top Source Markets | F38: Market Room-Nights (Out-of-Town) | G38: Lakeview Potential Room-Nights | H38: DIP Area ADR (AED) | I38: Hotel Impact
A39: 15–19 Mar 2027 | B39: Gulfood | C39: Expo City + DWTC | D39: 300,000 | E39: 195 countries (2026 actual benchmark) | F39: 187,500–375,000 | G39: 562–3,000 | H39: AED 494–551 | I39: VERY HIGH
A40: MAY 2027
A41: Dates | B41: Event | C41: Venue / Area | D41: Total Attendance | E41: Top Source Markets | F41: Market Room-Nights (Out-of-Town) | G41: Lakeview Potential Room-Nights | H41: DIP Area ADR (AED) | I41: Hotel Impact
A42: May 2027 (TBC) | B42: Seamless Middle East | C42: DWTC | D42: TBC | E42: Not published | F42: TBC | G42: TBC | H42: AED 410–437 | I42: MEDIUM
...
